<?xml version="1.0" encoding="utf-8" ?>
<!-- This URDF was automatically created by SolidWorks to URDF Exporter! Originally created by Stephen Brawner (brawner@gmail.com) 
     Commit Version: 1.6.0-1-g15f4949  Build Version: 1.6.7594.29634
     For more information, please see http://wiki.ros.org/sw_urdf_exporter -->
<robot name="project">
    <link name="base_link">
        
<inertial>
            <origin xyz="0.278340471985921 0.197898057709709 0.223523549393173" rpy="0 0 0" />
            <mass value="15.8691860759129" />
            <inertia ixx="0.0978878600572836" ixy="-3.43971760546347E-06" ixz="3.11042237695017E-06" iyy="0.25006769909136" iyz="3.30122479418386E-06" izz="0.254828115780011" />
        </inertial>

        <visual>
            <origin xyz="0 0 0" rpy="0 0 0" />
            <geometry>
                <mesh filename="package://project/meshes/base_link.STL" />
            </geometry>
            <material name="">
                <color rgba="0.792156862745098 0.819607843137255 0.933333333333333 1" />
            </material>
        </visual>
        <collision>
            <origin xyz="0 0 0" rpy="0 0 0" />
            <geometry>
                <mesh filename="package://project/meshes/base_link.STL" />
            </geometry>
        </collision>
    </link>
    <link name="world" />
    <joint name="fixed" type="fixed">
        <parent link="world" />
        <child link="base_link" />
    </joint>
    <link name="Link1">
        
<inertial>
            <origin xyz="0.16974 0.082252 0.096772" rpy="0 0 0" />
            <mass value="1.3237" />
            <inertia ixx="0.0030319" ixy="-0.00014178" ixz="-0.00029416" iyy="0.0040254" iyz="-7.4921E-05" izz="0.0033897" />
        </inertial>

        <visual>
            <origin xyz="0 0 0" rpy="0 0 0" />
            <geometry>
                <mesh filename="package://project/meshes/Link1.STL" />
            </geometry>
            <material name="">
                <color rgba="0.79216 0.81961 0.93333 1" />
            </material>
        </visual>
        <collision>
            <origin xyz="0 0 0" rpy="0 0 0" />
            <geometry>
                <mesh filename="package://project/meshes/Link1.STL" />
            </geometry>
        </collision>
    </link>
    <joint name="j1" type="continuous">
        <origin xyz="0.27699 -0.22256 0.39135" rpy="1.5708 0 0.54537" />
        <parent link="base_link" />
        <child link="Link1" />
        <axis xyz="0 1 0" />
    </joint>
    <link name="Link2">
        
<inertial>
            <origin xyz="-0.015475 -0.071109 0.066321" rpy="0 0 0" />
            <mass value="2.2372" />
            <inertia ixx="0.0041222" ixy="2.7294E-17" ixz="0.00033112" iyy="0.0022488" iyz="-4.8279E-17" izz="0.0037287" />
        </inertial>

        <visual>
            <origin xyz="0 0 0" rpy="0 0 0" />
            <geometry>
                <mesh filename="package://project/meshes/Link2.STL" />
            </geometry>
            <material name="">
                <color rgba="0.79216 0.81961 0.93333 1" />
            </material>
        </visual>
        <collision>
            <origin xyz="0 0 0" rpy="0 0 0" />
            <geometry>
                <mesh filename="package://project/meshes/Link2.STL" />
            </geometry>
        </collision>
    </link>
    <joint name="j2" type="prismatic">
        <origin xyz="0.3797 0 0.14093" rpy="0 0 0" />
        <parent link="Link1" />
        <child link="Link2" />
        <axis xyz="0 1 0" />
        <limit lower="-0.03" upper="0.14" effort="0" velocity="0" />
    </joint>
    <link name="Link3">
        
<inertial>
            <origin xyz="-0.018478 2.2204E-16 -0.061307" rpy="0 0 0" />
            <mass value="1.1787" />
            <inertia ixx="0.0035668" ixy="4.6693E-11" ixz="-7.1963E-18" iyy="0.0035773" iyz="1.7981E-17" izz="0.00011508" />
        </inertial>

        <visual>
            <origin xyz="0 0 0" rpy="0 0 0" />
            <geometry>
                <mesh filename="package://project/meshes/Link3.STL" />
            </geometry>
            <material name="">
                <color rgba="0.52941 0.54902 0.54902 1" />
            </material>
        </visual>
        <collision>
            <origin xyz="0 0 0" rpy="0 0 0" />
            <geometry>
                <mesh filename="package://project/meshes/Link3.STL" />
            </geometry>
        </collision>
    </link>
    <joint name="j3" type="prismatic">
        <origin xyz="-0.0020429 -0.12535 0.052704" rpy="-1.5708 1.0535 0" />
        <parent link="Link2" />
        <child link="Link3" />
        <axis xyz="0.5 0 0.86603" />
        <limit lower="0.0" upper="0.05" effort="0" velocity="0" />
    </joint>
    
<transmission name="trans_j1">
        <type>transmission_interface/SimpleTransmission</type>
        <joint name="j1">
            <hardwareInterface>hardware_interface/EffortJointInterface</hardwareInterface>
        </joint>
        <actuator name="j1_motor">
            <hardwareInterface>hardware_interface/EffortJointInterface</hardwareInterface>
            <mechanicalReduction>1</mechanicalReduction>
        </actuator>
    </transmission>
    <transmission name="trans_j2">
        <type>transmission_interface/SimpleTransmission</type>
        <joint name="j2">
            <hardwareInterface>hardware_interface/EffortJointInterface</hardwareInterface>
        </joint>
        <actuator name="j2_motor">
            <hardwareInterface>hardware_interface/EffortJointInterface</hardwareInterface>
            <mechanicalReduction>1</mechanicalReduction>
        </actuator>
    </transmission>
    <transmission name="trans_j3">
        <type>transmission_interface/SimpleTransmission</type>
        <joint name="j3">
            <hardwareInterface>hardware_interface/EffortJointInterface</hardwareInterface>
        </joint>
        <actuator name="j3_motor">
            <hardwareInterface>hardware_interface/EffortJointInterface</hardwareInterface>
            <mechanicalReduction>1</mechanicalReduction>
        </actuator>
    </transmission>
    <gazebo>
        <plugin name="gazebo_ros_control" filename="libgazebo_ros_control.so">
            <robotNamespace>/project</robotNamespace>
        </plugin>
    </gazebo>
</robot>
